<mujoco model="humanoid">
    <compiler angle="radian"/>
    <option gravity="0 0 -9.81"/>
    <default>
        <joint limited="true" armature="0.01" damping="2" />
    </default>
    <asset>
        <texture builtin="gradient" height="100" rgb1=".4 .5 .6" rgb2="0 0 0" type="skybox" width="100"/>
        <texture builtin="flat" height="1278" mark="cross" markrgb="1 1 1" name="texgeom" random="0.01" rgb1="0.8 0.6 0.4" rgb2="0.8 0.6 0.4" type="cube" width="127"/>
        <texture builtin="checker" height="100" name="texplane" rgb1="0 0 0" rgb2="0.8 0.8 0.8" type="2d" width="100"/>
        <material name="MatPlane" reflectance="0.5" shininess="1" specular="1" texrepeat="60 60" texture="texplane"/>
        <material name="geom" texture="texgeom" texuniform="true"/>
    </asset>
    <worldbody>
        <geom condim="3" material="MatPlane" name="floor" pos="0 0 -0.886" rgba="0.8 0.9 0.8 1" size="20 20 0.125" type="plane"/>
	<body name="root" pos="0.0 0.0 0.0">
		<geom type="sphere" name="root" mass="6.0" size="0.09" pos="0 0 0.07" rgba="0.4706 0.549 0.6863 0.5"/>
		<joint name="root" type="free" limited="true" pos="0 0 0" />
		<site type="sphere" name="joint_waist" pos="0 0 0.205" size="0.07" />
		<body name="chest" pos="0.0 0.0 0.236151">
			<geom type="sphere" name="chest" mass="14.0" size="0.11" pos="0 0 0.12" rgba="0.4706 0.549 0.6863 0.5"/>
			<joint type="hinge" name="chest_0" axis="1 0 0" pos="0 0 0" range="-1.2 1.2" limited="true" />
			<joint type="hinge" name="chest_1" axis="0 1 0" pos="0 0 0" range="-1.2 1.5" limited="true" />
			<joint type="hinge" name="chest_2" axis="0 0 1" pos="0 0 0" range="-1.4 1.4" limited="true" />
			<site type="capsule" name="right_clavicle" pos="-0.011 0.095 0.24" euler="-1.64 0.0338 -0.21" size="0.045 0.025" />
			<site type="capsule" name="left_clavicle" pos="-0.011 -0.095 0.24" euler="1.64 0.0338 0.21" size="0.045 0.025" />
			<body name="neck" pos="0.0 0.0 0.223894">
				<geom type="sphere" name="neck" mass="2.0" size="0.1025" pos="0 0 0.175" rgba="0.4706 0.549 0.6863 0.5"/>
				<joint type="hinge" name="neck_0" axis="1 0 0" pos="0 0 0" range="-1 1" limited="true" />
				<joint type="hinge" name="neck_1" axis="0 1 0" pos="0 0 0" range="-1 1.2" limited="true" />
				<joint type="hinge" name="neck_2" axis="0 0 1" pos="0 0 0" range="-1.4 1.4" limited="true" />
				<site type="sphere" name="joint_neck" pos="0 0 0.02" size="0.04" />
			</body>
			<body name="right_shoulder" pos="-0.02405 0.18311 0.2435">
				<geom type="capsule" name="right_shoulder" mass="1.5" fromto="0 0 -0.23 0 0 -0.05000000000000002" size="0.045" rgba="0.4706 0.549 0.6863 0.5"/>
				<joint type="hinge" name="right_shoulder_0" axis="1 0 0" pos="0 0 0" range="-3.14 0.5" limited="true" />
				<joint type="hinge" name="right_shoulder_1" axis="0 1 0" pos="0 0 0" range="-3.14 1.5" limited="true" />
				<joint type="hinge" name="right_shoulder_2" axis="0 0 1" pos="0 0 0" range="-0.7 3.14" limited="true" />
				<site type="sphere" name="joint_right_shoulder" pos="0 0 0" size="0.04" />
				<body name="right_elbow" pos="0.0 0.0 -0.274788">
					<geom type="capsule" name="right_elbow" mass="1" fromto="0 0 -0.1875 0 0 -0.05249999999999999" size="0.04" rgba="0.4706 0.549 0.6863 0.5"/>
					<joint name="right_elbow" type="hinge" pos="0 0 0" axis="0 -1 0" range="0 2.8" limited="true" />
					<site type="sphere" name="joint_right_elbow" pos="0 0 0" size="0.03" />
					<geom type="sphere" name="right_wrist" mass="0.5" size="0.04" pos="0.0 0.0 -0.258947" rgba="0.4706 0.549 0.6863 0.5"/>
				</body>
			</body>
			<body name="left_shoulder" pos="-0.02405 -0.18311 0.2435">
				<geom type="capsule" name="left_shoulder" mass="1.5" fromto="0 0 -0.23 0 0 -0.05000000000000002" size="0.045" rgba="0.4706 0.549 0.6863 0.5"/>
				<joint type="hinge" name="left_shoulder_0" axis="1 0 0" pos="0 0 0" range="-3.14 0.5" limited="true" />
				<joint type="hinge" name="left_shoulder_1" axis="0 1 0" pos="0 0 0" range="-3.14 1.5" limited="true" />
				<joint type="hinge" name="left_shoulder_2" axis="0 0 1" pos="0 0 0" range="-0.7 3.14" limited="true" />
				<site type="sphere" name="joint_left_shoulder" pos="0 0 0" size="0.04" />
				<body name="left_elbow" pos="0.0 0.0 -0.274788">
					<geom type="capsule" name="left_elbow" mass="1" fromto="0 0 -0.1875 0 0 -0.05249999999999999" size="0.04" rgba="0.4706 0.549 0.6863 0.5"/>
					<joint name="left_elbow" type="hinge" pos="0 0 0" axis="0 -1 0" range="0 2.8" limited="true" />
					<site type="sphere" name="joint_left_elbow" pos="0 0 0" size="0.03" />
					<geom type="sphere" name="left_wrist" mass="0.5" size="0.04" pos="0.0 0.0 -0.258947" rgba="0.4706 0.549 0.6863 0.5"/><!-- left_wrist is a None joint and does not require an explicit joint definition -->
				</body>
			</body>
		</body>
		<body name="right_hip" pos="0.0 0.084887 0.0">
			<geom type="capsule" name="right_hip" mass="4.5" fromto="0 0 -0.36 0 0 -0.06" size="0.055" rgba="0.4706 0.549 0.6863 0.5"/>
			<joint type="hinge" name="right_hip_0" axis="1 0 0" pos="0 0 0" range="-1.2 1.2" limited="true" />
			<joint type="hinge" name="right_hip_1" axis="0 1 0" pos="0 0 0" range="-1.2 1.2" limited="true" />
			<joint type="hinge" name="right_hip_2" axis="0 0 1" pos="0 0 0" range="-0.5 0.5" limited="true" />
			<site type="sphere" name="joint_right_hip" pos="0 0 0" size="0.045" />
			<body name="right_knee" pos="0.0 0.0 -0.421546">
				<geom type="capsule" name="right_knee" mass="3" fromto="0 0 -0.355 0 0 -0.04500000000000001" size="0.05" rgba="0.4706 0.549 0.6863 0.5"/>
				<joint name="right_knee" type="hinge" pos="0 0 0" axis="0 -1 0" range="-2.8 0" limited="true" />
				<site type="sphere" name="joint_right_knee" pos="0 0 0" size="0.035" />
				<body name="right_ankle" pos="0.0 0.0 -0.40987">
					<geom type="box" name="right_ankle" mass="1" size="0.0885 0.045 0.0275" pos="0.045 0 -0.0225" rgba="0.4706 0.549 0.6863 0.5"/>
					<joint type="hinge" name="right_ankle_0" axis="1 0 0" pos="0 0 0" range="-0.1 0.1" limited="true" />
					<joint type="hinge" name="right_ankle_1" axis="0 1 0" pos="0 0 0" range="-1 1" limited="true" />
					<joint type="hinge" name="right_ankle_2" axis="0 0 1" pos="0 0 0" range="-1 1" limited="true" />
					<site type="sphere" name="joint_right_ankle" pos="0 0 0" size="0.04" />
				</body>
			</body>
		</body>
		<body name="left_hip" pos="0.0 -0.084887 0.0">
			<geom type="capsule" name="left_hip" mass="4.5" fromto="0 0 -0.36 0 0 -0.06" size="0.055" rgba="0.4706 0.549 0.6863 0.5"/>
			<joint type="hinge" name="left_hip_0" axis="1 0 0" pos="0 0 0" range="-1.2 1.2" limited="true" />
			<joint type="hinge" name="left_hip_1" axis="0 1 0" pos="0 0 0" range="-1.2 1.2" limited="true" />
			<joint type="hinge" name="left_hip_2" axis="0 0 1" pos="0 0 0" range="-0.5 0.5" limited="true" />
			<site type="sphere" name="joint_left_hip" pos="0 0 0" size="0.045" />
			<body name="left_knee" pos="0.0 0.0 -0.421546">
				<geom type="capsule" name="left_knee" mass="3" fromto="0 0 -0.355 0 0 -0.04500000000000001" size="0.05" rgba="0.4706 0.549 0.6863 0.5"/>
				<joint name="left_knee" type="hinge" pos="0 0 0" axis="0 -1 0" range="-2.8 0" limited="true" />
				<site type="sphere" name="joint_left_knee" pos="0 0 0" size="0.035" />
				<body name="left_ankle" pos="0.0 0.0 -0.40987">
					<geom type="box" name="left_ankle" mass="1" size="0.0885 0.045 0.0275" pos="0.045 0 -0.0225" rgba="0.4706 0.549 0.6863 0.5"/>
					<joint type="hinge" name="left_ankle_0" axis="1 0 0" pos="0 0 0" range="-0.1 0.1" limited="true" />
					<joint type="hinge" name="left_ankle_1" axis="0 1 0" pos="0 0 0" range="-1 1" limited="true" />
					<joint type="hinge" name="left_ankle_2" axis="0 0 1" pos="0 0 0" range="-1 1" limited="true" />
					<site type="sphere" name="joint_left_ankle" pos="0 0 0" size="0.04" />
				</body>
			</body>
		</body>
	</body>
	</worldbody>
<actuator>
		<motor joint="chest_0" name="chest_0" gear="200.0" />
		<motor joint="chest_1" name="chest_1" gear="200.0" />
		<motor joint="chest_2" name="chest_2" gear="200.0" />
		<motor joint="neck_0" name="neck_0" gear="50.0" />
		<motor joint="neck_1" name="neck_1" gear="50.0" />
		<motor joint="neck_2" name="neck_2" gear="50.0" />
		<motor joint="right_shoulder_0" name="right_shoulder_0" gear="100.0" />
		<motor joint="right_shoulder_1" name="right_shoulder_1" gear="100.0" />
		<motor joint="right_shoulder_2" name="right_shoulder_2" gear="100.0" />
		<motor joint="right_elbow" name="right_elbow" gear="60.0" />
		<motor joint="left_shoulder_0" name="left_shoulder_0" gear="100.0" />
		<motor joint="left_shoulder_1" name="left_shoulder_1" gear="100.0" />
		<motor joint="left_shoulder_2" name="left_shoulder_2" gear="100.0" />
		<motor joint="left_elbow" name="left_elbow" gear="60.0" />
		<motor joint="right_hip_0" name="right_hip_0" gear="200.0" />
		<motor joint="right_hip_1" name="right_hip_1" gear="200.0" />
		<motor joint="right_hip_2" name="right_hip_2" gear="200.0" />
		<motor joint="right_knee" name="right_knee" gear="150.0" />
		<motor joint="right_ankle_0" name="right_ankle_0" gear="90.0" />
		<motor joint="right_ankle_1" name="right_ankle_1" gear="90.0" />
		<motor joint="right_ankle_2" name="right_ankle_2" gear="90.0" />
		<motor joint="left_hip_0" name="left_hip_0" gear="200.0" />
		<motor joint="left_hip_1" name="left_hip_1" gear="200.0" />
		<motor joint="left_hip_2" name="left_hip_2" gear="200.0" />
		<motor joint="left_knee" name="left_knee" gear="150.0" />
		<motor joint="left_ankle_0" name="left_ankle_0" gear="90.0" />
		<motor joint="left_ankle_1" name="left_ankle_1" gear="90.0" />
		<motor joint="left_ankle_2" name="left_ankle_2" gear="90.0" />
	</actuator>
</mujoco>